<?xml version="1.0" ?>
<mujoco model="robot_arm">
    <option timestep="0.01" />

    <asset>
        <material name="blue_" rgba="0 0 1 1" />
        <material name="green" rgba="0 1 0 1" />
        <material name="red__" rgba="1 0 0 1" />
        <material name="white" rgba="1 1 1 1" />
    </asset>

    <worldbody>
        <geom type="plane" size="15 15 0.1" pos="0 0 0" rgba=".9 0 0 1" />
        <light diffuse=".5 .5 .5" pos="0 0 3" dir="0 0 -1" />

        <!-- Base -->
        <body name="base" pos="0 0 0">
            <geom type="box" size="0.1 0.1 0.1" rgba="0 1 0 1" />

            <!-- Shoulder Pitch -->
            <body name="shoulder_pitch" pos="0 0 0.1">
                <joint name="shoulder_pitch_joint" type="hinge" pos="0 0 0" axis="1 0 0" range="-90 90" />
                <geom type="cylinder" size="0.05 0.1" pos="0 0 0" euler="90 0 0" mass="0.35"/>

                <!-- Shoulder Roll -->
                <body name="shoulder_roll" pos="0 0 0.1">
                    <joint name="shoulder_roll_joint" type="hinge" pos="0 0 0" axis="0 1 0" range="-90 90" />
                    <geom type="cylinder" size="0.05 0.1" pos="0 0 0" euler="0 0 0" mass="0.35"/>

                    <!-- Shoulder Yaw -->
                    <body name="shoulder_yaw" pos="0 0 0.1">
                        <joint name="shoulder_yaw_joint" type="hinge" pos="0 0 0" axis="0 0 1" range="-90 90" />
                        <geom type="cylinder" size="0.05 0.1" pos="0 0 0" euler="0 90 0" mass="0.35"/>

                        <!-- Link 1 -->
                        <body name="link_1" pos="0 0 0.1">
                            <geom type="capsule" size="0.02 0.1" pos="0 0 0.1" euler="90 0 0" mass="0.02"/>

                            <!-- Elbow Pitch -->
                            <body name="elbow_pitch" pos="0 0 0.2">
                                <joint name="elbow_pitch_joint" type="hinge" pos="0 0 0" axis="1 0 0" range="-90 90" />
                                <geom type="cylinder" size="0.05 0.1" pos="0 0 0" euler="0 0 0" mass="0.35"/>

                                <!-- Link 2 -->
                                <body name="link_2" pos="0 0 0.1">
                                    <geom type="capsule" size="0.02 0.1" pos="0 0 0.1" euler="90 0 0" mass="0.02"/>

                                    <!-- End Effector -->
                                    <body name="end_effector" pos="0 0 0.2">
                                        <geom type="sphere" size="0.05" pos="0 0 0" rgba="1 1 1 1" />
                                    </body>
                                </body>
                            </body>
                        </body>
                    </body>
                </body>
            </body>
        </body>
    </worldbody>

    <actuator>
        <motor gear="100" joint="shoulder_pitch_joint" name="actuator_shoulder_pitch" ctrlrange="-2.5 2.5" ctrllimited="true"/>
        <motor gear="100" joint="shoulder_roll_joint" name="actuator_shoulder_roll" ctrlrange="-2.5 2.5" ctrllimited="true"/>
        <motor gear="100" joint="shoulder_yaw_joint" name="actuator_shoulder_yaw" ctrlrange="-2.5 2.5" ctrllimited="true"/>
        <motor gear="100" joint="elbow_pitch_joint" name="actuator_elbow_pitch" ctrlrange="-2.5 2.5" ctrllimited="true"/>
    </actuator>
</mujoco>
